{
  "nbformat": 4,
  "nbformat_minor": 0,
  "metadata": {
    "colab": {
      "name": "Copy of Fmain.ipynb",
      "provenance": [],
      "authorship_tag": "ABX9TyN43Ym9xFXlrzZxtRb0kqEf",
      "include_colab_link": true
    },
    "kernelspec": {
      "name": "python3",
      "display_name": "Python 3"
    },
    "accelerator": "GPU"
  },
  "cells": [
    {
      "cell_type": "markdown",
      "metadata": {
        "id": "view-in-github",
        "colab_type": "text"
      },
      "source": [
        "<a href=\"https://colab.research.google.com/github/Rijwana1/project/blob/main/Copy_of_Fmain.ipynb\" target=\"_parent\"><img src=\"https://colab.research.google.com/assets/colab-badge.svg\" alt=\"Open In Colab\"/></a>"
      ]
    },
    {
      "cell_type": "code",
      "metadata": {
        "colab": {
          "base_uri": "https://localhost:8080/",
          "height": 895
        },
        "id": "aK6TyPaHmdBS",
        "outputId": "b4f3194c-8af3-43e0-eca2-7f0436248543"
      },
      "source": [
        "%cd ..\n",
        "from google.colab import drive\n",
        "drive.mount('/content/gdrive')"
      ],
      "execution_count": 16,
      "outputs": [
        {
          "output_type": "stream",
          "text": [
            "ERROR:root:Internal Python error in the inspect module.\n",
            "Below is the traceback from this internal error.\n",
            "\n"
          ],
          "name": "stderr"
        },
        {
          "output_type": "stream",
          "text": [
            "Traceback (most recent call last):\n",
            "  File \"/usr/local/lib/python3.7/dist-packages/IPython/core/interactiveshell.py\", line 2882, in run_code\n",
            "    exec(code_obj, self.user_global_ns, self.user_ns)\n",
            "  File \"<ipython-input-16-3f9a8cb01948>\", line 1, in <module>\n",
            "    get_ipython().magic('cd ..')\n",
            "  File \"/usr/local/lib/python3.7/dist-packages/IPython/core/interactiveshell.py\", line 2160, in magic\n",
            "    return self.run_line_magic(magic_name, magic_arg_s)\n",
            "  File \"/usr/local/lib/python3.7/dist-packages/IPython/core/interactiveshell.py\", line 2081, in run_line_magic\n",
            "    result = fn(*args,**kwargs)\n",
            "  File \"<decorator-gen-84>\", line 2, in cd\n",
            "  File \"/usr/local/lib/python3.7/dist-packages/IPython/core/magic.py\", line 188, in <lambda>\n",
            "    call = lambda f, *a, **k: f(*a, **k)\n",
            "  File \"/usr/local/lib/python3.7/dist-packages/IPython/core/magics/osm.py\", line 288, in cd\n",
            "    oldcwd = py3compat.getcwd()\n",
            "FileNotFoundError: [Errno 2] No such file or directory\n",
            "\n",
            "During handling of the above exception, another exception occurred:\n",
            "\n",
            "Traceback (most recent call last):\n",
            "  File \"/usr/local/lib/python3.7/dist-packages/IPython/core/interactiveshell.py\", line 1823, in showtraceback\n",
            "    stb = value._render_traceback_()\n",
            "AttributeError: 'FileNotFoundError' object has no attribute '_render_traceback_'\n",
            "\n",
            "During handling of the above exception, another exception occurred:\n",
            "\n",
            "Traceback (most recent call last):\n",
            "  File \"/usr/local/lib/python3.7/dist-packages/IPython/core/ultratb.py\", line 1132, in get_records\n",
            "    return _fixed_getinnerframes(etb, number_of_lines_of_context, tb_offset)\n",
            "  File \"/usr/local/lib/python3.7/dist-packages/IPython/core/ultratb.py\", line 313, in wrapped\n",
            "    return f(*args, **kwargs)\n",
            "  File \"/usr/local/lib/python3.7/dist-packages/IPython/core/ultratb.py\", line 358, in _fixed_getinnerframes\n",
            "    records = fix_frame_records_filenames(inspect.getinnerframes(etb, context))\n",
            "  File \"/usr/lib/python3.7/inspect.py\", line 1502, in getinnerframes\n",
            "    frameinfo = (tb.tb_frame,) + getframeinfo(tb, context)\n",
            "  File \"/usr/lib/python3.7/inspect.py\", line 1460, in getframeinfo\n",
            "    filename = getsourcefile(frame) or getfile(frame)\n",
            "  File \"/usr/lib/python3.7/inspect.py\", line 696, in getsourcefile\n",
            "    if getattr(getmodule(object, filename), '__loader__', None) is not None:\n",
            "  File \"/usr/lib/python3.7/inspect.py\", line 725, in getmodule\n",
            "    file = getabsfile(object, _filename)\n",
            "  File \"/usr/lib/python3.7/inspect.py\", line 709, in getabsfile\n",
            "    return os.path.normcase(os.path.abspath(_filename))\n",
            "  File \"/usr/lib/python3.7/posixpath.py\", line 383, in abspath\n",
            "    cwd = os.getcwd()\n",
            "FileNotFoundError: [Errno 2] No such file or directory\n"
          ],
          "name": "stdout"
        },
        {
          "output_type": "error",
          "ename": "FileNotFoundError",
          "evalue": "ignored",
          "traceback": [
            "\u001b[0;31m---------------------------------------------------------------------------\u001b[0m"
          ]
        }
      ]
    },
    {
      "cell_type": "code",
      "metadata": {
        "id": "_RQmLRvrm6YQ",
        "colab": {
          "base_uri": "https://localhost:8080/"
        },
        "outputId": "9444d8e4-9ec7-4d56-fd4f-261674d09b21"
      },
      "source": [
        "!ln -s /content/gdrive/My\\ Drive/ /mydrive"
      ],
      "execution_count": 14,
      "outputs": [
        {
          "output_type": "stream",
          "text": [
            "shell-init: error retrieving current directory: getcwd: cannot access parent directories: No such file or directory\n",
            "ln: failed to access '/mydrive': Transport endpoint is not connected\n"
          ],
          "name": "stdout"
        }
      ]
    },
    {
      "cell_type": "code",
      "metadata": {
        "id": "NU2irweznbvu",
        "colab": {
          "base_uri": "https://localhost:8080/",
          "height": 895
        },
        "outputId": "e968d0ae-5142-478f-d496-148a06ed0bd3"
      },
      "source": [
        "%cd /mydrive/yolov4"
      ],
      "execution_count": 9,
      "outputs": [
        {
          "output_type": "stream",
          "text": [
            "ERROR:root:Internal Python error in the inspect module.\n",
            "Below is the traceback from this internal error.\n",
            "\n"
          ],
          "name": "stderr"
        },
        {
          "output_type": "stream",
          "text": [
            "Traceback (most recent call last):\n",
            "  File \"/usr/local/lib/python3.7/dist-packages/IPython/core/interactiveshell.py\", line 2882, in run_code\n",
            "    exec(code_obj, self.user_global_ns, self.user_ns)\n",
            "  File \"<ipython-input-9-a561ab30ae22>\", line 1, in <module>\n",
            "    get_ipython().magic('cd /mydrive/yolov4')\n",
            "  File \"/usr/local/lib/python3.7/dist-packages/IPython/core/interactiveshell.py\", line 2160, in magic\n",
            "    return self.run_line_magic(magic_name, magic_arg_s)\n",
            "  File \"/usr/local/lib/python3.7/dist-packages/IPython/core/interactiveshell.py\", line 2081, in run_line_magic\n",
            "    result = fn(*args,**kwargs)\n",
            "  File \"<decorator-gen-84>\", line 2, in cd\n",
            "  File \"/usr/local/lib/python3.7/dist-packages/IPython/core/magic.py\", line 188, in <lambda>\n",
            "    call = lambda f, *a, **k: f(*a, **k)\n",
            "  File \"/usr/local/lib/python3.7/dist-packages/IPython/core/magics/osm.py\", line 288, in cd\n",
            "    oldcwd = py3compat.getcwd()\n",
            "FileNotFoundError: [Errno 2] No such file or directory\n",
            "\n",
            "During handling of the above exception, another exception occurred:\n",
            "\n",
            "Traceback (most recent call last):\n",
            "  File \"/usr/local/lib/python3.7/dist-packages/IPython/core/interactiveshell.py\", line 1823, in showtraceback\n",
            "    stb = value._render_traceback_()\n",
            "AttributeError: 'FileNotFoundError' object has no attribute '_render_traceback_'\n",
            "\n",
            "During handling of the above exception, another exception occurred:\n",
            "\n",
            "Traceback (most recent call last):\n",
            "  File \"/usr/local/lib/python3.7/dist-packages/IPython/core/ultratb.py\", line 1132, in get_records\n",
            "    return _fixed_getinnerframes(etb, number_of_lines_of_context, tb_offset)\n",
            "  File \"/usr/local/lib/python3.7/dist-packages/IPython/core/ultratb.py\", line 313, in wrapped\n",
            "    return f(*args, **kwargs)\n",
            "  File \"/usr/local/lib/python3.7/dist-packages/IPython/core/ultratb.py\", line 358, in _fixed_getinnerframes\n",
            "    records = fix_frame_records_filenames(inspect.getinnerframes(etb, context))\n",
            "  File \"/usr/lib/python3.7/inspect.py\", line 1502, in getinnerframes\n",
            "    frameinfo = (tb.tb_frame,) + getframeinfo(tb, context)\n",
            "  File \"/usr/lib/python3.7/inspect.py\", line 1460, in getframeinfo\n",
            "    filename = getsourcefile(frame) or getfile(frame)\n",
            "  File \"/usr/lib/python3.7/inspect.py\", line 696, in getsourcefile\n",
            "    if getattr(getmodule(object, filename), '__loader__', None) is not None:\n",
            "  File \"/usr/lib/python3.7/inspect.py\", line 725, in getmodule\n",
            "    file = getabsfile(object, _filename)\n",
            "  File \"/usr/lib/python3.7/inspect.py\", line 709, in getabsfile\n",
            "    return os.path.normcase(os.path.abspath(_filename))\n",
            "  File \"/usr/lib/python3.7/posixpath.py\", line 383, in abspath\n",
            "    cwd = os.getcwd()\n",
            "FileNotFoundError: [Errno 2] No such file or directory\n"
          ],
          "name": "stdout"
        },
        {
          "output_type": "error",
          "ename": "FileNotFoundError",
          "evalue": "ignored",
          "traceback": [
            "\u001b[0;31m---------------------------------------------------------------------------\u001b[0m"
          ]
        }
      ]
    },
    {
      "cell_type": "code",
      "metadata": {
        "id": "5BjY9HH1nj50"
      },
      "source": [
        "!git clone https://github.com/AlexeyAB/darknet"
      ],
      "execution_count": null,
      "outputs": []
    },
    {
      "cell_type": "code",
      "metadata": {
        "id": "hh5OB2p30eiu"
      },
      "source": [
        "from google.colab import drive\n",
        "drive.mount('/content/drive')"
      ],
      "execution_count": null,
      "outputs": []
    },
    {
      "cell_type": "code",
      "metadata": {
        "id": "nLRXzSwT0hnb"
      },
      "source": [
        "%cd darknet/"
      ],
      "execution_count": null,
      "outputs": []
    }
  ]
}